Workbook
Name Tmb_yes: tombol!$A$1:$A$2
Name Tombol: tombol!$A$1:$A$2

Sheet Data Unit kerja
A1: TIDAK DIANJURKAN mengubah pengaturan tabel penghitungan IPASN ini tanpa konfirmasi dengan BKPSDMD terlebih dulu
B3: DATA UNIT KERJA | M3: 4. CAPAIAN KINERJA PEGAWAI TAHUN 2016
B4: PENGHITUNGAN INDEKS PROFESIONALITAS APARATUR SIPIL NEGARA | M4: No | N4: Jabatan *) | O4: Nilai P2KP
M5: 1 | O5: 89
B6: ORGANISASI | C6: : | D6: PEMERINTAH KABUPATEN BANGKA | M6: 2 | O6: 84
B7: UNIT KERJA | C7: : | D7: diisi nama Unit Kerja | M7: 3 | O7: 86
B8: TAHUN | C8: : | D8: 42422 | M8: 4 | O8: 90
M9: 5 | O9: 80
B10: 1. JUMLAH JABATAN *) | C10: : | M10: 6 | O10: 75
B11: ESELON III | C11: : | D11: 2 | M11: 7 | O11: 80
B12: ESELON IV | C12: : | D12: 8 | M12: 8 | O12: 79
B13: JUMLAH | C13: : | D13: =SUM(D11:D12) -> 10 | M13: 9 | O13: 80
M14: 10 | O14: 80
B15: 2. DATA TUNJANGAN PERBAIKAN PENGHASILAN (BUKAN GAJI)
B17: ESELON | D17: TERTINGGI | E17: TERENDAH
B18: ESELON III | D18: 3500000 | E18: 3500000
B19: ESELON IV | D19: 1500000 | E19: 1250000 | M19: Jumlah | O19: =SUM(O5:O18) -> 823
M20: Rata-rata | O20: =O19/D13 -> 82.3
B21: 3. JUMLAH PEJABAT STRUKTURAL YANG DIJATUHI HUKUMAN DISIPLIN
B22: ESELON | D22: BERAT | E22: SEDANG | F22: RINGAN | M22: *) Jumlah jabatan pada angka 1 dan 4 harus sama
B23: ESELON III | D23: 0 | E23: 0 | F23: 1 | M23: Jika terdapat Jabatan yang kosong, nama jabatan tetap diisi, Nilai P2KP diisi dengan angka 0
B24: ESELON IV | D24: 0 | E24: 0 | F24: 1
B25: JUMLAH | D25: =SUM(D23:D24) -> 0 | E25: =SUM(E23:E24) -> 0 | F25: =SUM(F23:F24) -> 2
O26: =D48& ", "&TEXT(D49,"dd mmmm yyyy") -> Sungailiat, 27 Februari 2017
A27: **) CATATAN
A28: Petunjuk pengisian: | O28: Kerpala BKPSDMD
A29: 1. Kasubbag Umum / Pegelola Kepegawaian mengisi data kepegawaian terlebih dulu dari tab Data Unit Kerja (tab kuning)
A30: 2. Kasubbag Umum SKPD / Pengelola Kepegawaian mengisi data tab Kompetensi berdasarkan peta jabatan dengan komponen-komponen:
A31: a. Nama Jabatan sesuai Perda tentang SOTK OPD masing-masing
A32: b. Fungsi jabatan sesuai Peraturan Bupati Bangka tentang penjabaran Tugas/Fungsi OPD | O32: SURTAM, S.IP
A33: sebanyak maksimum 3 (tiga) yang menjadi core business jabatan | O33: NIP 19601211 198503 1 010
A34: c. Nama pejabat, NIP sesuai kolom yang disediakan
A35: d. Pendidikan (contoh S1 Ilmu Hukum)
A36: e. Pelatihan Teknis. (tuliskan jenis pelatihan teknis yang pernah diikuti s.d Tahun 2016)
A37: maksimum 3 (tiga) nama pelatihan (Contoh: Diklat SAKIP/Lakip, TOT, MOT, dll)
A38: f. Pengalaman. (Tuliskan pengalaman kerja/jabatan yang pernah dijabat sebelumnya)
A39: maksimum 3 (tiga) jabatan sebelumnya
A40: g. Administrasi atau Diklatpim; Tuliskan Diklatpim II/III/IV sesuai jabatannya
A41: Contoh: Agus saat ini menjabat sebagai Kepala Bidang Sistem Informasi,
A42: pada kolom Administrasi diisi Diklatpim III
...

Sheet 1. Kompetensi 
A2: Metode Penghitungan Kompetensi
A3: ='Data Unit kerja'!B45 -> UNIT KERJA : diisi nama Unit Kerja
A5: No. | B5: Jabatan | C5: Fungsi | E5: Nama Pejabat | F5: NIP | G5: Pendidikan | J5: Pelatihan | M5: Pengalaman | P5: Administrasi | S5: *Penilaian Objektif
I6: Y / N | L6: Y / N | O6: Y / N | R6: Y / N | S6: Gaps
A7: 1
Q33: Jumlah | S33: =SUM(S7:S7) -> 0
Q34: Gaps | S34: =S33/2 -> 0
D35: Kosong | E35: =COUNTIF(E7:E33,"-") -> 0 | H35: Y | I35: =COUNTIF(I7:I33,0) -> 0 | K35: Y | L35: =COUNTIF(L7:L33,0) -> 0 | N35: Y | O35: =COUNTIF(O7:O33,0) -> 0 | Q35: Y | R35: =COUNTIF(R7:R33,0) -> 0
H36: N | I36: =COUNTIF(I7:I33,1) -> 0 | K36: N | L36: =COUNTIF(L7:L33,1) -> 0 | N36: N | O36: =COUNTIF(O7:O33,1) -> 0 | Q36: N | R36: =COUNTIF(R7:R33,1) -> 0

Sheet 2. Kompensasi
A2: Metode Penghitungan Kompensasi
A3: ='Data Unit kerja'!B45 -> UNIT KERJA : diisi nama Unit Kerja
A4: Eselon | B4: Jumlah Pejabat | C4: Tertinggi | E4: Terendah | F4: Selisih | G4: Selisih terhadap Terendah
A5: III | B5: ='Data Unit kerja'!D11 -> 2 | D5: ='Data Unit kerja'!D18 -> 3500000 | E5: ='Data Unit kerja'!E18 -> 3500000 | F5: =D5-E5 -> 0 | G5: =+F5/E5 -> 0
A6: IV | B6: ='Data Unit kerja'!D12 -> 8 | D6: ='Data Unit kerja'!D19 -> 1500000 | E6: ='Data Unit kerja'!E19 -> 1250000 | F6: =D6-E6 -> 250000 | G6: =+F6/E6 -> 0.2
A8: Total | B8: ='Data Unit kerja'!D13 -> 10 | G8: =SUM(G5:G7) -> 0.2

Sheet 3. Kinerja
A2: Metode Penghitungan Kinerja
A3: Unit :
A4: Rata Rata Kinerja (SKP) | D4: =J18 -> 82.3 | H4: No | I4: Jabatan | J4: Nilai SKP
H5: 1 | I5: ='Data Unit kerja'!N5 -> 0 | J5: ='Data Unit kerja'!O5 -> 89
H6: 2 | I6: ='Data Unit kerja'!N6 -> 0 | J6: ='Data Unit kerja'!O6 -> 84
H7: 3 | I7: ='Data Unit kerja'!N7 -> 0 | J7: ='Data Unit kerja'!O7 -> 86
H8: 4 | I8: ='Data Unit kerja'!N8 -> 0 | J8: ='Data Unit kerja'!O8 -> 90
H9: 5 | I9: ='Data Unit kerja'!N9 -> 0 | J9: ='Data Unit kerja'!O9 -> 80
H10: 6 | I10: ='Data Unit kerja'!N10 -> 0 | J10: ='Data Unit kerja'!O10 -> 75
H11: 7 | I11: ='Data Unit kerja'!N11 -> 0 | J11: ='Data Unit kerja'!O11 -> 80
H12: 8 | I12: ='Data Unit kerja'!N12 -> 0 | J12: ='Data Unit kerja'!O12 -> 79
H13: 9 | I13: ='Data Unit kerja'!N13 -> 0 | J13: ='Data Unit kerja'!O13 -> 80
H14: 10 | I14: ='Data Unit kerja'!N14 -> 0 | J14: ='Data Unit kerja'!O14 -> 80
H17: Jumlah | J17: =SUM(J5:J16) -> 823
H18: Rata-rata | J18: =J17/'Data Unit kerja'!D13 -> 82.3

Sheet 4. Disiplin
A2: Metode Penghitungan Disiplin
A3: ='Data Unit kerja'!B45 -> UNIT KERJA : diisi nama Unit Kerja
A4: No | B4: Jenis Pelanggaran | C4: Jumlah | D4: Total
A5: 1 | B5: Berat | C5: ='Data Unit kerja'!D25 -> 0 | D5: =+C5*3 -> 0
A6: 2 | B6: Sedang | C6: ='Data Unit kerja'!E25 -> 0 | D6: =+C6*2 -> 0
A7: 3 | B7: Ringan | C7: ='Data Unit kerja'!F25 -> 2 | D7: =+C7 -> 2
B8: Total Pegawai | C8: ='Data Unit kerja'!D13 -> 10 | D8: =SUM(D5:D7) -> 2
C9: Pelanggaran | D9: =+D8/C8 -> 0.2

Sheet Cetak IPP
A1: Indeks Profesional Pegawai (IPP)
A2: ='Data Unit kerja'!D6 -> PEMERINTAH KABUPATEN BANGKA
A3: ='Data Unit kerja'!B46 -> TAHUN 2016
A4: ='Data Unit kerja'!B45 -> UNIT KERJA : diisi nama Unit Kerja
A6: No | B6: Unsur Penilaian | C6: Nilai
A7: A | B7: Kesenjangan (gap) Kompetensi | C7: ='1. Kompetensi '!S34 -> 0
A8: B | B8: Kesenjangan (gap) Kompensasi | C8: ='2. Kompensasi'!G8 -> 0.2 | E8: Rumus:
A9: C | B9: Kinerja | C9: ='3. Kinerja'!D4 -> 82.3 | E9: IPP | F9: = (25 x (1 - A)) + (25 x (1 -B)) + ((25 x C)/100) + (25 x (1 - D))
A10: D | B10: Indisipliner | C10: ='4. Disiplin'!D9 -> 0.2
A11: Indeks Profesional Pegawai (IPP) | C11: =(25*(1-C7))+(25*(1-C8))+((25*C9)/100)+(25*(1-C10)) -> 85.575
B13: Catatan:
B14: ="1. Kesenjangan Pendidikan = "&TEXT('1. Kompetensi '!I36-'1. Kompetensi '!E35,"0")&" pegawai." -> 1. Kesenjangan Pendidikan = 0 pegawai.
B15: ="2. Kesenjangan Pelatihan = "&TEXT('1. Kompetensi '!L36-'1. Kompetensi '!E35,"0")&" pegawai." -> 2. Kesenjangan Pelatihan = 0 pegawai.
B16: ="3. Kesenjangan Pengalaman = "&TEXT('1. Kompetensi '!O36-'1. Kompetensi '!E35,"0")&" pegawai." -> 3. Kesenjangan Pengalaman = 0 pegawai.
B17: ="4. Kesenjangan Administrasi = "&TEXT('1. Kompetensi '!R36-'1. Kompetensi '!E35,"0")&" pegawai." -> 4. Kesenjangan Administrasi = 0 pegawai.
B18: ="5. Jabatan Kosong = "&TEXT('1. Kompetensi '!E35,"0")&"" -> 5. Jabatan Kosong = 0
C19: ='Data Unit kerja'!O26 -> Sungailiat, 27 Februari 2017
C21: ='Data Unit kerja'!O28 -> Kerpala BKPSDMD
C26: ='Data Unit kerja'!O32 -> SURTAM, S.IP
C27: ='Data Unit kerja'!O33 -> NIP 19601211 198503 1 010

Sheet CATATAN
B1: *Catatan:
A2: A | B2: - Pendidikan = Pendidikan formal (PF)
B3: - Pelatihan = Pelatihan yang pernah diikuti (LAT)
B4: - Pengalaman = Jabatan yang pernah diduduki (LAM)
A5: B | B5: Diklat Administrasi = Diklat Kepemimpinan (LATPIM), dll
B7: * Yes = Jika semua A Yes dan B Yes
B8: * Yes = Jika salah satu A Yes dan B Yes
B9: * No = Jika semua atau salah satu A No dan B Yes
B10: * No = Jika semua atau salah satu A Yes dan B No
B11: * No = Jika semua atau salah satu A No dan B No

Sheet tombol
A1: 0 | D1: 1 | F1: 1 | H1: 0 | J1: 1 | L1: Gaps | M1: =+D1+F1+H1+J1 -> 3
A2: 1
D7: 0
