Workbook
Name Tmb_yes: tombol!$A$1:$A$2
Name Tombol: tombol!$A$1:$A$2

Sheet Data Unit kerja
A1: TIDAK DIANJURKAN mengubah pengaturan tabel penghitungan IPASN ini tanpa konfirmasi dengan BKPSDMD terlebih dulu
B3: DATA UNIT KERJA | N3: 4. CAPAIAN KINERJA PEGAWAI TAHUN 2016
B4: PENGHITUNGAN INDEKS PROFESIONALITAS APARATUR SIPIL NEGARA | N4: No | O4: Jabatan *) | P4: Nilai P2KP
N5: 1 | P5: 80
B6: ORGANISASI | D6: : | E6: PEMERINTAH KABUPATEN BANGKA | N6: 2 | P6: 80
B7: UNIT KERJA | D7: : | E7: diisi nama Unit Kerja | N7: 3 | P7: 80
B8: TAHUN | D8: : | E8: 42422 | N8: 4 | P8: 80
N9: 5 | P9: 80
B10: 1. JUMLAH JABATAN *) | D10: : | N10: 6 | P10: 80
B11: ESELON II | D11: : | E11: 1 | N11: 7 | P11: 80
B12: ESELON III | D12: : | E12: 6 | N12: 8 | P12: 80
B13: ESELON IV | D13: : | E13: 18 | N13: 9 | P13: 80
B14: JUMLAH | D14: : | E14: =SUM(E11:E13) -> 25 | N14: 10 | P14: 80
N15: 11 | P15: 80
B16: 2. DATA TUNJANGAN PERBAIKAN PENGHASILAN (BUKAN GAJI) | N16: 12 | P16: 80
N17: 13 | P17: 80
B18: ESELON | E18: TERTINGGI | F18: TERENDAH | N18: 14 | P18: 80
B19: ESELON II | E19: 4000000 | F19: 4000000 | N19: 15 | P19: 80
B20: ESELON III | E20: 2500000 | F20: 2450000 | N20: 16 | P20: 80
B21: ESELON IV | E21: 2000000 | F21: 1750000 | N21: 17 | P21: 80
N22: 18 | P22: 80
B23: 3. JUMLAH PEJABAT STRUKTURAL YANG DIJATUHI HUKUMAN DISIPLIN | N23: 19 | P23: 80
B24: ESELON | E24: BERAT | F24: SEDANG | G24: RINGAN | N24: 20 | P24: 80
B25: ESELON II | E25: 0 | F25: 0 | G25: 1 | N25: 21 | P25: 80
B26: ESELON III | E26: 0 | F26: 0 | G26: 1 | N26: 22 | P26: 80
B27: ESELON IV | E27: 0 | F27: 0 | G27: 1 | N27: 23 | P27: 80
B28: JUMLAH | E28: =SUM(E25:E27) -> 0 | F28: =SUM(F25:F27) -> 0 | G28: =SUM(G25:G27) -> 3 | N28: 24 | P28: 80
N29: 25 | P29: 80
N30: Jumlah | P30: =SUM(P5:P29) -> 2000
N31: Rata-rata | P31: =P30/E14 -> 80
N33: *) Jumlah jabatan pada angka 1 dan 4 harus sama
A34: **) CATATAN | N34: Jika terdapat Jabatan yang kosong, nama jabatan tetap diisi, Nilai P2KP diisi dengan angka 0
A35: Petunjuk pengisian:
A36: 1. Kasubbag Umum / Pegelola Kepegawaian mengisi data kepegawaian terlebih dulu dari tab Data Unit Kerja (tab kuning)
A37: 2. Kasubbag Umum SKPD / Pengelola Kepegawaian mengisi data tab Kompetensi berdasarkan peta jabatan dengan komponen-komponen:
A38: a. Nama Jabatan sesuai Perda tentang SOTK OPD masing-masing
A39: b. Fungsi jabatan sesuai Peraturan Bupati Bangka tentang penjabaran Tugas/Fungsi OPD
A40: sebanyak maksimum 3 (tiga) yang menjadi core business jabatan
A41: c. Nama pejabat, NIP sesuai kolom yang disediakan
A42: d. Pendidikan (contoh S1 Ilmu Hukum)
...

Sheet 1. Kompetensi 
A2: Metode Penghitungan Kompetensi
A3: ='Data Unit kerja'!B55 -> UNIT KERJA : diisi nama Unit Kerja
A5: No. | B5: Jabatan | C5: Fungsi | E5: Nama Pejabat | F5: NIP | G5: Pendidikan | J5: Pelatihan | M5: Pengalaman | P5: Administrasi | S5: *Penilaian Objektif
I6: Y / N | L6: Y / N | O6: Y / N | R6: Y / N | S6: Gaps
C7: 1
C8: 2
C9: 3
Q70: Jumlah | S70: =SUM(S7:S69) -> 0
Q71: Gaps | S71: =S70/2 -> 0
D72: Kosong | E72: =COUNTIF(E7:E70,"-") -> 0 | H72: Y | I72: =COUNTIF(I7:I70,0) -> 0 | K72: Y | L72: =COUNTIF(L7:L70,0) -> 0 | N72: Y | O72: =COUNTIF(O7:O70,0) -> 0 | Q72: Y | R72: =COUNTIF(R7:R70,0) -> 0
H73: N | I73: =COUNTIF(I7:I70,1) -> 0 | K73: N | L73: =COUNTIF(L7:L70,1) -> 0 | N73: N | O73: =COUNTIF(O7:O70,1) -> 0 | Q73: N | R73: =COUNTIF(R7:R70,1) -> 0

Sheet 2. Kompensasi
A2: Metode Penghitungan Kompensasi
A3: ='Data Unit kerja'!B55 -> UNIT KERJA : diisi nama Unit Kerja
A4: Eselon | B4: Jumlah Pejabat | C4: Tertinggi | E4: Terendah | F4: Selisih | G4: Selisih terhadap Terendah
A5: II | B5: ='Data Unit kerja'!E11 -> 1 | D5: ='Data Unit kerja'!E19 -> 4000000 | E5: ='Data Unit kerja'!F19 -> 4000000 | F5: =D5-E5 -> 0 | G5: =+F5/E5 -> 0
A6: III | B6: ='Data Unit kerja'!E12 -> 6 | D6: ='Data Unit kerja'!E20 -> 2500000 | E6: ='Data Unit kerja'!F20 -> 2450000 | F6: =D6-E6 -> 50000 | G6: =+F6/E6 -> 0.020408163
A7: IV | B7: ='Data Unit kerja'!E13 -> 18 | D7: ='Data Unit kerja'!E21 -> 2000000 | E7: ='Data Unit kerja'!F21 -> 1750000 | F7: =D7-E7 -> 250000 | G7: =+F7/E7 -> 0.14285714
A9: Total | B9: ='Data Unit kerja'!E14 -> 25 | G9: =SUM(G5:G8) -> 0.16326531

Sheet 3. Kinerja
A2: Metode Penghitungan Kinerja
A3: ='2. Kompensasi'!A3 -> UNIT KERJA : diisi nama Unit Kerja
A4: Rata Rata Kinerja (SKP) | D4: =J31 -> 80 | H4: No | I4: Jabatan | J4: Nilai SKP
H5: 1 | I5: ='Data Unit kerja'!O5 -> 0 | J5: ='Data Unit kerja'!P5 -> 80
H6: 2 | I6: ='Data Unit kerja'!O6 -> 0 | J6: ='Data Unit kerja'!P6 -> 80
H7: 3 | I7: ='Data Unit kerja'!O7 -> 0 | J7: ='Data Unit kerja'!P7 -> 80
H8: 4 | I8: ='Data Unit kerja'!O8 -> 0 | J8: ='Data Unit kerja'!P8 -> 80
H9: 5 | I9: ='Data Unit kerja'!O9 -> 0 | J9: ='Data Unit kerja'!P9 -> 80
H10: 6 | I10: ='Data Unit kerja'!O10 -> 0 | J10: ='Data Unit kerja'!P10 -> 80
H11: 7 | I11: ='Data Unit kerja'!O11 -> 0 | J11: ='Data Unit kerja'!P11 -> 80
H12: 8 | I12: ='Data Unit kerja'!O12 -> 0 | J12: ='Data Unit kerja'!P12 -> 80
H13: 9 | I13: ='Data Unit kerja'!O13 -> 0 | J13: ='Data Unit kerja'!P13 -> 80
H14: 10 | I14: ='Data Unit kerja'!O14 -> 0 | J14: ='Data Unit kerja'!P14 -> 80
H15: 11 | I15: ='Data Unit kerja'!O15 -> 0 | J15: ='Data Unit kerja'!P15 -> 80
H16: 12 | I16: ='Data Unit kerja'!O16 -> 0 | J16: ='Data Unit kerja'!P16 -> 80
... H29: 25 | I29: ='Data Unit kerja'!O29 -> 0 | J29: ='Data Unit kerja'!P29 -> 80
H30: Jumlah | J30: =SUM(J5:J29) -> 2000
H31: Rata-rata | J31: =J30/'Data Unit kerja'!E14 -> 80

Sheet 4. Disiplin
A2: Metode Penghitungan Disiplin
A3: ='Data Unit kerja'!B55 -> UNIT KERJA : diisi nama Unit Kerja
A4: No | B4: Jenis Pelanggaran | C4: Jumlah | D4: Total
A5: 1 | B5: Berat | C5: ='Data Unit kerja'!E28 -> 0 | D5: =+C5*3 -> 0
A6: 2 | B6: Sedang | C6: ='Data Unit kerja'!F28 -> 0 | D6: =+C6*2 -> 0
A7: 3 | B7: Ringan | C7: ='Data Unit kerja'!G28 -> 3 | D7: =+C7 -> 3
B8: Total Pegawai | C8: ='Data Unit kerja'!E14 -> 25 | D8: =SUM(D5:D7) -> 3
C9: Pelanggaran | D9: =+D8/C8 -> 0.12

Sheet Cetak IPP
A1: Indeks Profesional Pegawai (IPP)
A2: ='Data Unit kerja'!E6 -> PEMERINTAH KABUPATEN BANGKA
A3: ='Data Unit kerja'!B56 -> TAHUN 2016
A4: ='Data Unit kerja'!B55 -> UNIT KERJA : diisi nama Unit Kerja
A6: No | B6: Unsur Penilaian | C6: Nilai
A7: A | B7: Gap Kompetensi | C7: ='1. Kompetensi '!S71 -> 0
A8: B | B8: Gap Kompensasi | C8: ='2. Kompensasi'!$G$9 -> 0.16326531 | E8: Rumus:
A9: C | B9: Kinerja | C9: ='3. Kinerja'!D4 -> 80 | E9: IPP | F9: = (25 x (1 - A)) + (25 x (1 -B)) + ((25 x C)/100) + (25 x (1 - D))
A10: D | B10: Indisipliner | C10: ='4. Disiplin'!D9 -> 0.12
A11: Indeks Profesional Pegawai (IPP) | C11: =(25*(1-C7))+(25*(1-C8))+((25*C9)/100)+(25*(1-C10)) -> 87.918367
B13: Catatan:
B14: ="1. Kesenjangan Pendidikan = "&TEXT('1. Kompetensi '!I73-'1. Kompetensi '!E72,"0")&" pegawai." -> 1. Kesenjangan Pendidikan = 0 pegawai.
B15: ="2. Kesenjangan Pelatihan = "&TEXT('1. Kompetensi '!L73-'1. Kompetensi '!E72,"0")&" pegawai." -> 2. Kesenjangan Pelatihan = 0 pegawai.
B16: ="3. Kesenjangan Pengalaman = "&TEXT('1. Kompetensi '!O73-'1. Kompetensi '!E72,"0")&" pegawai." -> 3. Kesenjangan Pengalaman = 0 pegawai.
B17: ="4. Kesenjangan Administrasi = "&TEXT('1. Kompetensi '!R73-'1. Kompetensi '!E72,"0")&" pegawai." -> 4. Kesenjangan Administrasi = 0 pegawai.
B18: ="5. Jabatan Kosong = "&TEXT('1. Kompetensi '!E72,"0")&"" -> 5. Jabatan Kosong = 0

Sheet CATATAN
B1: *Catatan:
A2: A | B2: - Pendidikan = Pendidikan formal (PF)
B3: - Pelatihan = Pelatihan yang pernah diikuti (LAT)
B4: - Pengalaman = Jabatan yang pernah diduduki (LAM)
A5: B | B5: Diklat Administrasi = Diklat Kepemimpinan (LATPIM), dll
B7: * Yes = Jika semua A Yes dan B Yes
B8: * Yes = Jika salah satu A Yes dan B Yes
B9: * No = Jika semua atau salah satu A No dan B Yes
B10: * No = Jika semua atau salah satu A Yes dan B No
B11: * No = Jika semua atau salah satu A No dan B No

Sheet tombol
A1: 0 | D1: 1 | F1: 1 | H1: 0 | J1: 1 | L1: Gaps | M1: =+D1+F1+H1+J1 -> 3
A2: 1
D7: 0

Sheet Sheet1
C3: disdik
C4: 5 | D4: =5*3 -> 15
